## 에러 처리

- 사용자 정의 예외(user-defined exceptions)
- 내부 에러 처리(internal error handling): 잘못된 연산자, 지원되지 않는 연산 시도 등에 대한 처리

1. **내부 에러 처리는 사실상 return문과 동일**. 일련의 명령문을 실행하던 도중 error object를 만나면 에러 원인을 값으로 감싸며 **평가를 중단**하며 탈출.

2. 상용 인터프리터의 경우 문제가 발생한 지점의 행과 열 번호를 함께 넣어 **stack trace**를 남기는 것이 일반적! 이를 위해서는 렉서에 정보 필요!

```go
package object

const ERROR_OBJ = "ERROR"

type Error struct {
	Message string
}

func (e *Error) Type() ObjectType { return ERROR_OBJ }
func (e *Error) Inspect() string  { return "ERROR: " + e.Message }
```

```go
// evaluator.go
func evalProgram(program *ast.Program, env *object.Environment) object.Object {
	var result object.Object

	for _, statement := range program.Statements {
		result = Eval(statement, env)

		switch result := result.(type) {
		case *object.ReturnValue:
			return result.Value
		case *object.Error:
			return result
		}
	}

	return result
}

func evalBlockStatement(
	block *ast.BlockStatement,
	env *object.Environment,
) object.Object {
	var result object.Object

	for _, statement := range block.Statements {
		result = Eval(statement, env)

		if result != nil {
			rt := result.Type()
			if rt == object.RETURN_VALUE_OBJ || rt == object.ERROR_OBJ {
				return result
			}
		}
	}

	return result
}

func newError(format string, a ...interface{}) *object.Error {
	return &object.Error{Message: fmt.Sprintf(format, a...)}
}
```

Eval 내부에서 Eval을 호출했을 때 error object가 나오면 early return시켜주도록 명시 필요.

```go
func Eval(node ast.Node, env *object.Environment) object.Object {
	switch node := node.(type) {

	// Statements
	case *ast.ReturnStatement:
		val := Eval(node.ReturnValue, env)
		if isError(val) {
			return val
		}
		return &object.ReturnValue{Value: val}

	case *ast.LetStatement:
		val := Eval(node.Value, env)
		if isError(val) {
			return val
		}
		env.Set(node.Name.Value, val)
    // ...
	}
}
```
